[2021-01-10 04:26:40 -0500] [4123] [ERROR] Exception in worker process
Traceback (most recent call last):
  File "/usr/local/lib/python3.7/site-packages/gunicorn/arbiter.py", line 583, in spawn_worker
    worker.init_process()
  File "/usr/local/lib/python3.7/site-packages/gunicorn/workers/base.py", line 129, in init_process
    self.load_wsgi()
  File "/usr/local/lib/python3.7/site-packages/gunicorn/workers/base.py", line 138, in load_wsgi
    self.wsgi = self.app.wsgi()
  File "/usr/local/lib/python3.7/site-packages/gunicorn/app/base.py", line 67, in wsgi
    self.callable = self.load()
  File "/usr/local/lib/python3.7/site-packages/psiturk/experiment_server.py", line 48, in load
    return util.import_app("psiturk.experiment:app")
  File "/usr/local/lib/python3.7/site-packages/gunicorn/util.py", line 350, in import_app
    __import__(module)
  File "/usr/local/lib/python3.7/site-packages/psiturk/experiment.py", line 77, in <module>
    from custom import custom_code
  File "/Users/a3055/iat/custom.py", line 61
    try:
       ^
TabError: inconsistent use of tabs and spaces in indentation
[2021-01-10 04:26:41 -0500] [4124] [ERROR] Exception in worker process
Traceback (most recent call last):
  File "/usr/local/lib/python3.7/site-packages/gunicorn/arbiter.py", line 583, in spawn_worker
    worker.init_process()
  File "/usr/local/lib/python3.7/site-packages/gunicorn/workers/base.py", line 129, in init_process
    self.load_wsgi()
  File "/usr/local/lib/python3.7/site-packages/gunicorn/workers/base.py", line 138, in load_wsgi
    self.wsgi = self.app.wsgi()
  File "/usr/local/lib/python3.7/site-packages/gunicorn/app/base.py", line 67, in wsgi
    self.callable = self.load()
  File "/usr/local/lib/python3.7/site-packages/psiturk/experiment_server.py", line 48, in load
    return util.import_app("psiturk.experiment:app")
  File "/usr/local/lib/python3.7/site-packages/gunicorn/util.py", line 350, in import_app
    __import__(module)
  File "/usr/local/lib/python3.7/site-packages/psiturk/experiment.py", line 77, in <module>
    from custom import custom_code
  File "/Users/a3055/iat/custom.py", line 61
    try:
       ^
TabError: inconsistent use of tabs and spaces in indentation
[2021-01-10 04:26:41 -0500] [4125] [ERROR] Exception in worker process
Traceback (most recent call last):
  File "/usr/local/lib/python3.7/site-packages/gunicorn/arbiter.py", line 583, in spawn_worker
    worker.init_process()
  File "/usr/local/lib/python3.7/site-packages/gunicorn/workers/base.py", line 129, in init_process
    self.load_wsgi()
  File "/usr/local/lib/python3.7/site-packages/gunicorn/workers/base.py", line 138, in load_wsgi
    self.wsgi = self.app.wsgi()
  File "/usr/local/lib/python3.7/site-packages/gunicorn/app/base.py", line 67, in wsgi
    self.callable = self.load()
  File "/usr/local/lib/python3.7/site-packages/psiturk/experiment_server.py", line 48, in load
    return util.import_app("psiturk.experiment:app")
  File "/usr/local/lib/python3.7/site-packages/gunicorn/util.py", line 350, in import_app
    __import__(module)
  File "/usr/local/lib/python3.7/site-packages/psiturk/experiment.py", line 77, in <module>
    from custom import custom_code
  File "/Users/a3055/iat/custom.py", line 61
    try:
       ^
TabError: inconsistent use of tabs and spaces in indentation
[2021-01-10 04:26:41 -0500] [4126] [ERROR] Exception in worker process
Traceback (most recent call last):
  File "/usr/local/lib/python3.7/site-packages/gunicorn/arbiter.py", line 583, in spawn_worker
    worker.init_process()
  File "/usr/local/lib/python3.7/site-packages/gunicorn/workers/base.py", line 129, in init_process
    self.load_wsgi()
  File "/usr/local/lib/python3.7/site-packages/gunicorn/workers/base.py", line 138, in load_wsgi
    self.wsgi = self.app.wsgi()
  File "/usr/local/lib/python3.7/site-packages/gunicorn/app/base.py", line 67, in wsgi
    self.callable = self.load()
  File "/usr/local/lib/python3.7/site-packages/psiturk/experiment_server.py", line 48, in load
    return util.import_app("psiturk.experiment:app")
  File "/usr/local/lib/python3.7/site-packages/gunicorn/util.py", line 350, in import_app
    __import__(module)
  File "/usr/local/lib/python3.7/site-packages/psiturk/experiment.py", line 77, in <module>
    from custom import custom_code
  File "/Users/a3055/iat/custom.py", line 61
    try:
       ^
TabError: inconsistent use of tabs and spaces in indentation
[2021-01-10 04:26:41 -0500] [4128] [ERROR] Exception in worker process
Traceback (most recent call last):
  File "/usr/local/lib/python3.7/site-packages/gunicorn/arbiter.py", line 583, in spawn_worker
    worker.init_process()
  File "/usr/local/lib/python3.7/site-packages/gunicorn/workers/base.py", line 129, in init_process
    self.load_wsgi()
  File "/usr/local/lib/python3.7/site-packages/gunicorn/workers/base.py", line 138, in load_wsgi
    self.wsgi = self.app.wsgi()
  File "/usr/local/lib/python3.7/site-packages/gunicorn/app/base.py", line 67, in wsgi
    self.callable = self.load()
  File "/usr/local/lib/python3.7/site-packages/psiturk/experiment_server.py", line 48, in load
    return util.import_app("psiturk.experiment:app")
  File "/usr/local/lib/python3.7/site-packages/gunicorn/util.py", line 350, in import_app
    __import__(module)
  File "/usr/local/lib/python3.7/site-packages/psiturk/experiment.py", line 77, in <module>
    from custom import custom_code
  File "/Users/a3055/iat/custom.py", line 61
    try:
       ^
TabError: inconsistent use of tabs and spaces in indentation
[2021-01-10 04:26:41 -0500] [4127] [ERROR] Exception in worker process
Traceback (most recent call last):
  File "/usr/local/lib/python3.7/site-packages/gunicorn/arbiter.py", line 583, in spawn_worker
    worker.init_process()
  File "/usr/local/lib/python3.7/site-packages/gunicorn/workers/base.py", line 129, in init_process
    self.load_wsgi()
  File "/usr/local/lib/python3.7/site-packages/gunicorn/workers/base.py", line 138, in load_wsgi
    self.wsgi = self.app.wsgi()
  File "/usr/local/lib/python3.7/site-packages/gunicorn/app/base.py", line 67, in wsgi
    self.callable = self.load()
  File "/usr/local/lib/python3.7/site-packages/psiturk/experiment_server.py", line 48, in load
    return util.import_app("psiturk.experiment:app")
  File "/usr/local/lib/python3.7/site-packages/gunicorn/util.py", line 350, in import_app
    __import__(module)
  File "/usr/local/lib/python3.7/site-packages/psiturk/experiment.py", line 77, in <module>
    from custom import custom_code
  File "/Users/a3055/iat/custom.py", line 61
    try:
       ^
TabError: inconsistent use of tabs and spaces in indentation
[2021-01-10 04:26:41 -0500] [4129] [ERROR] Exception in worker process
Traceback (most recent call last):
  File "/usr/local/lib/python3.7/site-packages/gunicorn/arbiter.py", line 583, in spawn_worker
    worker.init_process()
  File "/usr/local/lib/python3.7/site-packages/gunicorn/workers/base.py", line 129, in init_process
    self.load_wsgi()
  File "/usr/local/lib/python3.7/site-packages/gunicorn/workers/base.py", line 138, in load_wsgi
    self.wsgi = self.app.wsgi()
  File "/usr/local/lib/python3.7/site-packages/gunicorn/app/base.py", line 67, in wsgi
    self.callable = self.load()
  File "/usr/local/lib/python3.7/site-packages/psiturk/experiment_server.py", line 48, in load
    return util.import_app("psiturk.experiment:app")
  File "/usr/local/lib/python3.7/site-packages/gunicorn/util.py", line 350, in import_app
    __import__(module)
  File "/usr/local/lib/python3.7/site-packages/psiturk/experiment.py", line 77, in <module>
    from custom import custom_code
  File "/Users/a3055/iat/custom.py", line 61
    try:
       ^
TabError: inconsistent use of tabs and spaces in indentation
[2021-01-10 04:26:41 -0500] [4130] [ERROR] Exception in worker process
Traceback (most recent call last):
  File "/usr/local/lib/python3.7/site-packages/gunicorn/arbiter.py", line 583, in spawn_worker
    worker.init_process()
  File "/usr/local/lib/python3.7/site-packages/gunicorn/workers/base.py", line 129, in init_process
    self.load_wsgi()
  File "/usr/local/lib/python3.7/site-packages/gunicorn/workers/base.py", line 138, in load_wsgi
    self.wsgi = self.app.wsgi()
  File "/usr/local/lib/python3.7/site-packages/gunicorn/app/base.py", line 67, in wsgi
    self.callable = self.load()
  File "/usr/local/lib/python3.7/site-packages/psiturk/experiment_server.py", line 48, in load
    return util.import_app("psiturk.experiment:app")
  File "/usr/local/lib/python3.7/site-packages/gunicorn/util.py", line 350, in import_app
    __import__(module)
  File "/usr/local/lib/python3.7/site-packages/psiturk/experiment.py", line 77, in <module>
    from custom import custom_code
  File "/Users/a3055/iat/custom.py", line 61
    try:
       ^
TabError: inconsistent use of tabs and spaces in indentation
[2021-01-10 04:26:41 -0500] [4131] [ERROR] Exception in worker process
Traceback (most recent call last):
  File "/usr/local/lib/python3.7/site-packages/gunicorn/arbiter.py", line 583, in spawn_worker
    worker.init_process()
  File "/usr/local/lib/python3.7/site-packages/gunicorn/workers/base.py", line 129, in init_process
    self.load_wsgi()
  File "/usr/local/lib/python3.7/site-packages/gunicorn/workers/base.py", line 138, in load_wsgi
    self.wsgi = self.app.wsgi()
  File "/usr/local/lib/python3.7/site-packages/gunicorn/app/base.py", line 67, in wsgi
    self.callable = self.load()
  File "/usr/local/lib/python3.7/site-packages/psiturk/experiment_server.py", line 48, in load
    return util.import_app("psiturk.experiment:app")
  File "/usr/local/lib/python3.7/site-packages/gunicorn/util.py", line 350, in import_app
    __import__(module)
  File "/usr/local/lib/python3.7/site-packages/psiturk/experiment.py", line 77, in <module>
    from custom import custom_code
  File "/Users/a3055/iat/custom.py", line 61
    try:
       ^
TabError: inconsistent use of tabs and spaces in indentation
[2021-01-10 05:20:50 -0500] [4659] [CRITICAL] WORKER TIMEOUT (pid:4669)
2021-01-10 06:57:43,855 hit_assign_worker_id_not_set_in_mturk (1001) {}
